<?xml version="1.0" ?>
<robot name="myrt" xmlns:xacro="http://www.ros.org/wiki/xacro">

<xacro:include filename="$(find myrt_description)/urdf/materials.xacro" />
<xacro:include filename="$(find myrt_description)/urdf/myrt.trans" />
<xacro:include filename="$(find myrt_description)/urdf/myrt.gazebo" />

<link name="world"/>

<link name="base_link">
  <inertial>
    <origin xyz="0.08 0.09249999999999968 0.07996229424977229" rpy="0 0 0"/>
    <mass value="37.199178814539344"/>
    <inertia ixx="0.185521" iyy="0.158923" izz="0.185637" ixy="0.0" iyz="-0.0" ixz="0.0"/>
  </inertial>
  <visual>
    <origin xyz="0 0 0" rpy="0 0 0"/>
    <geometry>
      <mesh filename="file://$(find myrt_description)/meshes/base_link.stl" scale="0.001 0.001 0.001"/>
    </geometry>
    <material name="silver"/>
  </visual>
  <collision>
    <origin xyz="0 0 0" rpy="0 0 0"/>
    <geometry>
      <mesh filename="file://$(find myrt_description)/meshes/base_link.stl" scale="0.001 0.001 0.001"/>
    </geometry>
  </collision>
</link>

<link name="rr_link_1">
  <inertial>
    <origin xyz="-0.010000000000000009 -1.3600232051658168e-15 -6.938893903907228e-18" rpy="0 0 0"/>
    <mass value="0.6011241193103218"/>
    <inertia ixx="0.00037" iyy="0.000205" izz="0.000205" ixy="0.0" iyz="0.0" ixz="0.0"/>
  </inertial>
  <visual>
    <origin xyz="-0.195 -0.155 -0.015" rpy="0 0 0"/>
    <geometry>
      <mesh filename="file://$(find myrt_description)/meshes/rr_link_1.stl" scale="0.001 0.001 0.001"/>
    </geometry>
    <material name="silver"/>
  </visual>
  <collision>
    <origin xyz="-0.195 -0.155 -0.015" rpy="0 0 0"/>
    <geometry>
      <mesh filename="file://$(find myrt_description)/meshes/rr_link_1.stl" scale="0.001 0.001 0.001"/>
    </geometry>
  </collision>
</link>

<link name="lf_link_1">
  <inertial>
    <origin xyz="0.010000000000000002 1.3322676295501878e-15 3.469446951953614e-18" rpy="0 0 0"/>
    <mass value="0.6011241193103217"/>
    <inertia ixx="0.00037" iyy="0.000205" izz="0.000205" ixy="-0.0" iyz="-0.0" ixz="-0.0"/>
  </inertial>
  <visual>
    <origin xyz="0.035 -0.03 -0.015" rpy="0 0 0"/>
    <geometry>
      <mesh filename="file://$(find myrt_description)/meshes/lf_link_1.stl" scale="0.001 0.001 0.001"/>
    </geometry>
    <material name="silver"/>
  </visual>
  <collision>
    <origin xyz="0.035 -0.03 -0.015" rpy="0 0 0"/>
    <geometry>
      <mesh filename="file://$(find myrt_description)/meshes/lf_link_1.stl" scale="0.001 0.001 0.001"/>
    </geometry>
  </collision>
</link>

<link name="lr_link_1">
  <inertial>
    <origin xyz="0.010000000000000002 1.3600232051658168e-15 -6.938893903907228e-18" rpy="0 0 0"/>
    <mass value="0.6011241193103218"/>
    <inertia ixx="0.00037" iyy="0.000205" izz="0.000205" ixy="-0.0" iyz="0.0" ixz="-0.0"/>
  </inertial>
  <visual>
    <origin xyz="0.035 -0.155 -0.015" rpy="0 0 0"/>
    <geometry>
      <mesh filename="file://$(find myrt_description)/meshes/lr_link_1.stl" scale="0.001 0.001 0.001"/>
    </geometry>
    <material name="silver"/>
  </visual>
  <collision>
    <origin xyz="0.035 -0.155 -0.015" rpy="0 0 0"/>
    <geometry>
      <mesh filename="file://$(find myrt_description)/meshes/lr_link_1.stl" scale="0.001 0.001 0.001"/>
    </geometry>
  </collision>
</link>

<link name="rf_link_1">
  <inertial>
    <origin xyz="-0.010000000000000009 -1.3357370765021415e-15 0.0" rpy="0 0 0"/>
    <mass value="0.6011241193103218"/>
    <inertia ixx="0.00037" iyy="0.000205" izz="0.000205" ixy="0.0" iyz="-0.0" ixz="0.0"/>
  </inertial>
  <visual>
    <origin xyz="-0.195 -0.03 -0.015" rpy="0 0 0"/>
    <geometry>
      <mesh filename="file://$(find myrt_description)/meshes/rf_link_1.stl" scale="0.001 0.001 0.001"/>
    </geometry>
    <material name="silver"/>
  </visual>
  <collision>
    <origin xyz="-0.195 -0.03 -0.015" rpy="0 0 0"/>
    <geometry>
      <mesh filename="file://$(find myrt_description)/meshes/rf_link_1.stl" scale="0.001 0.001 0.001"/>
    </geometry>
  </collision>
</link>

<joint name="Revolute 2" type="continuous">
  <origin xyz="0.195 0.155 0.015" rpy="0 0 0"/>
  <parent link="base_link"/>
  <child link="rr_link_1"/>
  <axis xyz="1.0 0.0 0.0"/>
</joint>

<joint name="Revolute 3" type="continuous">
  <origin xyz="-0.035 0.03 0.015" rpy="0 0 0"/>
  <parent link="base_link"/>
  <child link="lf_link_1"/>
  <axis xyz="-1.0 0.0 0.0"/>
</joint>

<joint name="Revolute 4" type="continuous">
  <origin xyz="-0.035 0.155 0.015" rpy="0 0 0"/>
  <parent link="base_link"/>
  <child link="lr_link_1"/>
  <axis xyz="-1.0 0.0 0.0"/>
</joint>

<joint name="Revolute 5" type="continuous">
  <origin xyz="0.195 0.03 0.015" rpy="0 0 0"/>
  <parent link="base_link"/>
  <child link="rf_link_1"/>
  <axis xyz="1.0 0.0 0.0"/>
</joint>

</robot>
